Workbook

Sheet A 3000
A1: University | C1: King Mongkut's University of Techonology Thonburi | L1: Car # | N1: EV-02 | T1: Part Cost | V1: =Y18+AA23+S34+U41+S46 -> 3183.8753
A2: System | C2: FR | T2: Qty | V2: 1
A3: Assembly | L3: Filelink1
A4: Part | C4: FRAME AND BODY ASSEMBLY | L4: Filelink 2 | T4: Extended Cost | V4: =V1*V2 -> 3183.8753
A5: P/N Base | C5: A0100 | L5: Filelink 3
A6: Suffix | C6: AA
A7: Details | L7: Item Order | N7: Part | R7: Part Cost | W7: Quantity | Y7: Subtotal
L8: 1 | N8: FRAME ASSEMBLY | R8: ='FR 00200-AA'!V1 -> 459.5463 | W8: ='FR 00200-AA'!V2 -> 1 | Y8: =R8*W8 -> 459.5463
L9: 2 | N9: SUSPENSION MOUNTING ASSEMBLY | R9: ='FR 00300-AA'!V1 -> 110.73 | W9: ='FR 00300-AA'!V2 -> 1 | Y9: =R9*W9 -> 110.73
L10: 3 | N10: ELECTRICAL MOUNTING ASSEMBLY | R10: ='FR 00400-AA'!V1 -> 83.4448 | W10: ='FR 00400-AA'!V2 -> 1 | Y10: =R10*W10 -> 83.4448
L11: 4 | N11: COOLING MOUTING ASSEMBLY | R11: ='FR A0500-AA'!V1 -> 5.724 | W11: ='FR A0500-AA'!V2 -> 1 | Y11: =R11*W11 -> 5.724
L12: 5 | N12: ANTI INTRUSION PLATE | R12: ='FR A0600-AA'!V1 -> 9.0625 | W12: ='FR A0600-AA'!V2 -> 1 | Y12: =R12*W12 -> 9.0625
L13: 6 | N13: BODY ASSEMBLY | R13: ='FR A0700-AA'!V1 -> 2206.6774 | W13: ='FR A0700-AA'!V2 -> 1 | Y13: =R13*W13 -> 2206.6774
L14: 7 | N14: FRAME JIG ASSEMBLY | R14: ='FR A0800-AA'!V1 -> 70.22 | W14: ='FR A0800-AA'!V2 -> 1 | Y14: =R14*W14 -> 70.22
L15: 8 | N15: DRIVETRAIN MOUNTING ASSEMBLY | R15: ='FR A0900-AA'!V1 -> 10.4108 | W15: ='FR A0900-AA'!V2 -> 1 | Y15: =R15*W15 -> 10.4108
L16: 9 | N16: DRIVERS PROTECTION MOUNTING | R16: ='FR A1000-AA'!V1 -> 79.45 | W16: ='FR A1000-AA'!V2 -> 1 | Y16: =R16*W16 -> 79.45
L17: 10 | N17: A-ARM BRACKET JIG | R17: =' FR A1100-AA'!V1 -> 26.0295 | W17: =' FR A1100-AA'!V2 -> 1 | Y17: =R17*W17 -> 26.0295
W18: Subtotal | Y18: =SUM(Y8:Z17) -> 3061.2953
A20: Item Order | C20: Material | F20: Use | I20: Unit Cost | K20: Size ( 1 ) | M20: Unit ( 1 ) | O20: Size ( 2 ) | Q20: Unit ( 2 ) | S20: Area Name | U20: Area | V20: Length | W20: Density | Y20: Quantity | AA20: Sub Total
Y23: Sub Total
A25: Item Order | C25: Process | F25: Use | I25: Unit Cost | K25: Unit | M25: Quantity | O25: Multiplier | Q25: Mult. Val. | S25: Sub Total
A26: 1 | C26: Assemble, >20 kg, Line-on-Line | F26: Assemble frame tube together | I26: 3.75 | K26: unit | M26: 1 | O26: - | Q26: 1 | S26: =I26*M26*Q26 -> 3.75
A27: 2 | C27: Tube end preperation for welding | F27: Preperation for welding | I27: 0.75 | K27: end | M27: 1 | O27: - | Q27: 1 | S27: =I27*M27*Q27 -> 0.75
A28: 3 | C28: Weld | F28: welding suspension mounting with frame | I28: 0.15 | K28: cm | M28: 410.11 | O28: - | Q28: 1 | S28: =I28*M28*Q28 -> 61.5165
A29: 4 | C29: Weld | F29: welding electrical mounting with frame | I29: 0.15 | K29: cm | M29: 116.12 | O29: - | Q29: 1 | S29: =I29*M29*Q29 -> 17.418
A30: 5 | C30: Weld | F30: welding cooling mounting with frame | I30: 0.15 | K30: cm | M30: 1 | O30: - | Q30: 1 | S30: =I30*M30*Q30 -> 0.15
A31: 6 | C31: Weld | F31: welding anti intrusion plate with frame | I31: 0.15 | K31: cm | M31: 144 | O31: - | Q31: 1 | S31: =I31*M31*Q31 -> 21.6
A32: 7 | C32: Weld | F32: welding drivetrain mounting with frame | I32: 0.15 | K32: cm | M32: 35.12 | O32: - | Q32: 1 | S32: =I32*M32*Q32 -> 5.268
A33: 8 | C33: Weld | F33: welding protection mounting with frame | I33: 0.15 | K33: cm | M33: 74.85 | O33: - | Q33: 1 | S33: =I33*M33*Q33 -> 11.2275
Q34: Sub Total | S34: =SUM(S26:T33) -> 121.68
A38: Item Order | C38: Fastener | F38: Use | I38: Unit Cost | K38: Size ( 1 ) | M38: Unit ( 1 ) | O38: Size ( 2 ) | Q38: Unit ( 2 ) | S38: Quantity | U38: Sub Total
A39: 1 | C39: Rivet, Pop | F39: Fasten body assembly with mounting | I39: 0.03 | K39: - | M39: - | O39: - | Q39: - | S39: 30 | U39: =I39*S39 -> 0.9
S41: Sub Total | U41: =SUM(U39:V40) -> 0.9
A43: Item Order | C43: Tooling | F43: Use | I43: Unit Cost | K43: Unit | M43: Quantity | O43: PVF | Q43: Frac Incld. | S43: Sub Total
Q46: Sub Total

Sheet FR 00200-AA
A1: University | C1: King Mongkut's University of Techonology Thonburi | L1: Car # | N1: EV-02 | T1: Part Cost | V1: =Y78+S89+S99+U94+AA83 -> 459.5463
A2: System | C2: FR | T2: Qty | V2: 1
A3: Assembly | C3: FRAME AND BODY ASSEMBLY | L3: Filelink1
A4: Part | C4: FRAME ASSEMBLY | L4: Filelink 2 | T4: Extended Cost | V4: =V1*V2 -> 459.5463
A5: P/N Base | C5: A0200 | L5: Filelink 3
A6: Suffix | C6: AA
A7: Details | L7: Item Order | N7: Part | R7: Part Cost | W7: Quantity | Y7: Subtotal
L8: 1 | N8: Frame Tube 1 | R8: ='FR 00201-AA'!V1 -> 2.3689 | W8: 1 | Y8: =R8*W8 -> 2.3689
L9: 2 | N9: Frame Tube 2 | R9: ='FR 00202-AA'!V1 -> 2.809 | W9: 1 | Y9: =R9*W9 -> 2.809
L10: 3 | N10: Front Hoop Bracing 1 | R10: ='FR 00203-AA'!V1 -> 3.9727 | W10: 1 | Y10: =R10*W10 -> 3.9727
L11: 4 | N11: Frame Tube 3 | R11: ='FR 00204-AA'!V1 -> 2.1166 | W11: 1 | Y11: =R11*W11 -> 2.1166
L12: 5 | N12: Frame Tube 4 | R12: ='FR 00205-AA'!V1 -> 3.3367 | W12: 1 | Y12: =R12*W12 -> 3.3367
L13: 6 | N13: Frame Tube 5 | R13: ='FR 00206-AA'!V1 -> 3.0496 | W13: 1 | Y13: =R13*W13 -> 3.0496
L14: 7 | N14: Front Bulkhead Tube 1 | R14: ='FR 00207-AA'!V1 -> 3.8891 | W14: 1 | Y14: =R14*W14 -> 3.8891
L15: 8 | N15: Front Bulkhead Tube 2 | R15: ='FR 00208-AA'!V1 -> 3.9473 | W15: 1 | Y15: =R15*W15 -> 3.9473
L16: 9 | N16: Front Bulkhead Tube 3 | R16: ='FR 00209-AA'!V1 -> 4.2218 | W16: 1 | Y16: =R16*W16 -> 4.2218
L17: 10 | N17: Front Bulkhead Tube 4 | R17: ='FR 00210-AA'!V1 -> 3.8891 | W17: 1 | Y17: =R17*W17 -> 3.8891
L18: 11 | N18: Front Bulkhead Tube 5 | R18: ='FR 00211-AA'!V1 -> 3.9473 | W18: 1 | Y18: =R18*W18 -> 3.9473
L19: 12 | N19: Frame Tube 6 | R19: ='FR 00212-AA'!V1 -> 4.4588 | W19: 1 | Y19: =R19*W19 -> 4.4588
L20: 13 | N20: Frame Tube 7 | R20: ='FR 00213-AA'!V1 -> 2.1688 | W20: 1 | Y20: =R20*W20 -> 2.1688
L21: 14 | N21: Front Hoop | R21: ='FR 00214-AA'!V1 -> 9.079 | W21: 1 | Y21: =R21*W21 -> 9.079
L22: 15 | N22: Front Hoop Bracing 2 | R22: ='FR 00215-AA'!V1 -> 3.9727 | W22: 1 | Y22: =R22*W22 -> 3.9727
L23: 16 | N23: Frame Tube 8 | R23: ='FR 00216-AA'!V1 -> 2.2474 | W23: 1 | Y23: =R23*W23 -> 2.2474
L24: 17 | N24: Frame Tube 9 | R24: ='FR 00217-AA'!V1 -> 2.2699 | W24: 1 | Y24: =R24*W24 -> 2.2699
L25: 18 | N25: Frame Tube 10 | R25: ='FR 00218-AA'!V1 -> 4.6286 | W25: 1 | Y25: =R25*W25 -> 4.6286
L26: 19 | N26: Frame Tube 11 | R26: ='FR 00219-AA'!V1 -> 4.3568 | W26: 1 | Y26: =R26*W26 -> 4.3568
L27: 20 | N27: Frame Tube 12 | R27: ='FR 00220-AA'!V1 -> 4.1384 | W27: 1 | Y27: =R27*W27 -> 4.1384
L28: 21 | N28: Frame Tube 13 | R28: ='FR 00221-AA'!V1 -> 2.10985 | W28: 1 | Y28: =R28*W28 -> 2.10985
L29: 22 | N29: Frame Tube 14 | R29: ='FR 00222-AA'!V1 -> 2.4388 | W29: 1 | Y29: =R29*W29 -> 2.4388
L30: 23 | N30: Frame Tube 15 | R30: ='FR 00223-AA'!V1 -> 2.4103 | W30: 1 | Y30: =R30*W30 -> 2.4103
L31: 24 | N31: Frame Tube 16 | R31: ='FR 00224-AA'!V1 -> 2.8201 | W31: 1 | Y31: =R31*W31 -> 2.8201
L32: 25 | N32: Shoulder Harness Bracing 1 | R32: ='FR 00225-AA'!V1 -> 2.2285 | W32: 1 | Y32: =R32*W32 -> 2.2285
L33: 26 | N33: Main Hoop | R33: ='FR 00226-AA'!V1 -> 11.3863 | W33: 1 | Y33: =R33*W33 -> 11.3863
L34: 27 | N34: Sholder Harness | R34: ='FR 00227-AA'!V1 -> 4.9867 | W34: 1 | Y34: =R34*W34 -> 4.9867
L35: 28 | N35: Shoulder Harness Bracing 2 | R35: ='FR 00228-AA'!V1 -> 2.2285 | W35: 1 | Y35: =R35*W35 -> 2.2285
L36: 29 | N36: Frame Tube 17 | R36: ='FR 00229-AA'!V1 -> 2.82748 | W36: 1 | Y36: =R36*W36 -> 2.82748
L37: 30 | N37: Frame Tube 18 | R37: ='FR 00230-AA'!V1 -> 3.47482 | W37: 1 | Y37: =R37*W37 -> 3.47482
L38: 31 | N38: Frame Tube 19 | R38: ='FR 00231-AA'!V1 -> 2.7187 | W38: 1 | Y38: =R38*W38 -> 2.7187
L39: 32 | N39: Frame Tube 20 | R39: ='FR 00232-AA'!V1 -> 2.8765 | W39: 1 | Y39: =R39*W39 -> 2.8765
L40: 33 | N40: Frame Tube 21 | R40: ='FR 00233-AA'!V1 -> 2.5306 | W40: 1 | Y40: =R40*W40 -> 2.5306
...

Sheet สำเนาของ AA 30001
A1: University | C1: King Mongkut's University of Techonology Thonburi | L1: Car # | N1: EV-02 | T1: Part Cost
A2: System | C2: FR | T2: Qty
A3: Assembly | C3: Frame Assembly | L3: Filelink1
A4: Part | C4: - | L4: Filelink 2 | T4: Extended Cost
A5: P/N Base | C5: 30001 | L5: Filelink 3
A6: Suffix | C6: AA
A7: Details | L7: Item Order | N7: Part | R7: Part Cost | W7: Quantity | Y7: Subtotal
L8: 1 | N8: Frame Tube 1 | R8: ='FR 00201-AA'!V1 -> 2.3689 | W8: 1 | Y8: =R8*W8 -> 2.3689
L9: 2 | N9: Frame Tube 2 | R9: ='FR 00202-AA'!V1 -> 2.809 | W9: 1 | Y9: =R9*W9 -> 2.809
L10: 3 | N10: Front Hoop Bracing 1 | R10: ='FR 00203-AA'!V1 -> 3.9727 | W10: 1 | Y10: =R10*W10 -> 3.9727
L11: 4 | N11: Frame Tube 3 | R11: ='FR 00204-AA'!V1 -> 2.1166 | W11: 1 | Y11: =R11*W11 -> 2.1166
L12: 5 | N12: Frame Tube 4 | R12: ='FR 00205-AA'!V1 -> 3.3367 | W12: 1 | Y12: =R12*W12 -> 3.3367
L13: 6 | N13: Frame Tube 5 | R13: ='FR 00206-AA'!V1 -> 3.0496 | W13: 1 | Y13: =R13*W13 -> 3.0496
L14: 7 | N14: Front Bulkhead Tube 1 | R14: ='FR 00207-AA'!V1 -> 3.8891 | W14: 1 | Y14: =R14*W14 -> 3.8891
L15: 8 | N15: Front Bulkhead Tube 2 | R15: ='FR 00208-AA'!V1 -> 3.9473 | W15: 1 | Y15: =R15*W15 -> 3.9473
L16: 9 | N16: Front Bulkhead Tube 3 | R16: ='FR 00209-AA'!V1 -> 4.2218 | W16: 1 | Y16: =R16*W16 -> 4.2218
L17: 10 | N17: Front Bulkhead Tube 4 | R17: ='FR 00210-AA'!V1 -> 3.8891 | W17: 1 | Y17: =R17*W17 -> 3.8891
L18: 11 | N18: Front Bulkhead Tube 5 | R18: ='FR 00211-AA'!V1 -> 3.9473 | W18: 1 | Y18: =R18*W18 -> 3.9473
L19: 12 | N19: Frame Tube 6 | R19: ='FR 00212-AA'!V1 -> 4.4588 | W19: 1 | Y19: =R19*W19 -> 4.4588
L20: 13 | N20: Frame Tube 7 | R20: ='FR 00213-AA'!V1 -> 2.1688 | W20: 1 | Y20: =R20*W20 -> 2.1688
L21: 14 | N21: Front Hoop | R21: ='FR 00214-AA'!V1 -> 9.079 | W21: 1 | Y21: =R21*W21 -> 9.079
L22: 15 | N22: Front Hoop Bracing 2 | R22: ='FR 00215-AA'!V1 -> 3.9727 | W22: 1 | Y22: =R22*W22 -> 3.9727
L23: 16 | N23: Frame Tube 8 | R23: ='FR 00216-AA'!V1 -> 2.2474 | W23: 1 | Y23: =R23*W23 -> 2.2474
L24: 17 | N24: Frame Tube 9 | R24: ='FR 00217-AA'!V1 -> 2.2699 | W24: 1 | Y24: =R24*W24 -> 2.2699
L25: 18 | N25: Frame Tube 10 | R25: ='FR 00218-AA'!V1 -> 4.6286 | W25: 1 | Y25: =R25*W25 -> 4.6286
L26: 19 | N26: Frame Tube 11 | R26: ='FR 00219-AA'!V1 -> 4.3568 | W26: 1 | Y26: =R26*W26 -> 4.3568
L27: 20 | N27: Frame Tube 12 | R27: ='FR 00220-AA'!V1 -> 4.1384 | W27: 1 | Y27: =R27*W27 -> 4.1384
L28: 21 | N28: Frame Tube 13 | R28: ='FR 00221-AA'!V1 -> 2.10985 | W28: 1 | Y28: =R28*W28 -> 2.10985
L29: 22 | N29: Frame Tube 14 | R29: ='AA 30001-22'!V1 -> #REF! | W29: 1 | Y29: =R29*W29 -> #REF!
L30: 23 | N30: Frame Tube 15 | R30: ='FR 00223-AA'!V1 -> 2.4103 | W30: 1 | Y30: =R30*W30 -> 2.4103
L31: 24 | N31: Frame Tube 16 | R31: ='AA 30001-24'!V1 -> #REF! | W31: 1 | Y31: =R31*W31 -> #REF!
L32: 25 | N32: Shoulder Harness Bracing 1 | R32: ='FR 00225-AA'!V1 -> 2.2285 | W32: 1 | Y32: =R32*W32 -> 2.2285
L33: 26 | N33: Main Hoop | R33: ='FR 00226-AA'!V1 -> 11.3863 | W33: 1 | Y33: =R33*W33 -> 11.3863
L34: 27 | N34: Sholder Harness | R34: ='FR 00227-AA'!V1 -> 4.9867 | W34: 1 | Y34: =R34*W34 -> 4.9867
L35: 28 | N35: Shoulder Harness Bracing 2 | R35: ='FR 00228-AA'!V1 -> 2.2285 | W35: 1 | Y35: =R35*W35 -> 2.2285
L36: 29 | N36: Frame Tube 17 | R36: ='FR 00229-AA'!V1 -> 2.82748 | W36: 1 | Y36: =R36*W36 -> 2.82748
L37: 30 | N37: Frame Tube 18 | R37: ='FR 00230-AA'!V1 -> 3.47482 | W37: 1 | Y37: =R37*W37 -> 3.47482
L38: 31 | N38: Frame Tube 19 | R38: ='FR 00231-AA'!V1 -> 2.7187 | W38: 1 | Y38: =R38*W38 -> 2.7187
L39: 32 | N39: Frame Tube 20 | R39: ='FR 00232-AA'!V1 -> 2.8765 | W39: 1 | Y39: =R39*W39 -> 2.8765
L40: 33 | N40: Frame Tube 21 | R40: ='FR 00233-AA'!V1 -> 2.5306 | W40: 1 | Y40: =R40*W40 -> 2.5306
...

Sheet 0000
A1: University | C1: King Mongkut's University of Techonology Thonburi | L1: Car # | N1: EV-02 | T1: Part Cost
A2: System | C2: FR | T2: Qty
A3: Assembly | L3: Filelink1
A4: Part | L4: Filelink 2 | T4: Extended Cost
A5: P/N Base | L5: Filelink 3
A6: Suffix
A7: Details
A11: Item Order | C11: Material | F11: Use | I11: Unit Cost | K11: Size ( 1 ) | M11: Unit ( 1 ) | O11: Size ( 2 ) | Q11: Unit ( 2 ) | S11: Area Name | U11: Area | V11: Length | W11: Density | Y11: Quantity | AA11: Sub Total
Y14: Sub Total
A16: Item Order | C16: Process | F16: Use | I16: Unit Cost | K16: Unit | M16: Quantity | O16: Multiplier | Q16: Mult. Val. | S16: Sub Total
Q19: Sub Total
A21: Item Order | C21: Fastener | F21: Use | I21: Unit Cost | K21: Size ( 1 ) | M21: Unit ( 1 ) | O21: Size ( 2 ) | Q21: Unit ( 2 ) | S21: Quantity | U21: Sub Total
S24: Sub Total
A26: Item Order | C26: Tooling | F26: Use | I26: Unit Cost | K26: Unit | M26: Quantity | O26: PVF | Q26: Frac Incld. | S26: Sub Total
Q29: Sub Total

Sheet FR 00201-AA
A1: University | C1: King Mongkut's University of Techonology Thonburi | L1: Car # | N1: EV-02 | T1: Part Cost | V1: =AA14+S19+U24+S29 -> 2.3689
A2: System | C2: FR | T2: Qty | V2: 1
A3: Assembly | C3: Frame Assembly | L3: Filelink1
A4: Part | C4: Frame tube 1 | L4: Filelink 2 | T4: Extended Cost | V4: =V1*V2 -> 2.3689
A5: P/N Base | C5: 00201 | L5: Filelink 3
A6: Suffix | C6: AA
A7: Details
A11: Item Order | C11: Material | F11: Use | I11: Unit Cost | K11: Size ( 1 ) | M11: Unit ( 1 ) | O11: Size ( 2 ) | Q11: Unit ( 2 ) | S11: Area Name | U11: Area | V11: Length | W11: Density | Y11: Quantity | AA11: Sub Total
A12: 1 | C12: Tubing, Steel | F12: Frame tube | I12: 2.25 | K12: 0.21 | M12: kg | O12: - | Q12: - | S12: Circle | U12: 91.27 mm^2 | V12: 293.32 mm | W12: - | Y12: 1 | AA12: =I12*K12*Y12 -> 0.4725
Y14: Sub Total | AA14: =SUM(AA12:AB13) -> 0.4725
A16: Item Order | C16: Process | F16: Use | I16: Unit Cost | K16: Unit | M16: Quantity | O16: Multiplier | Q16: Mult. Val. | S16: Sub Total
A17: 1 | C17: Machining Setup, Install and remove | F17: Setup the laser cut machine | I17: 1.3 | K17: Unit | M17: 1 | O17: - | Q17: 1 | S17: =I17*M17*Q17 -> 1.3
A18: 2 | C18: Laser Cut | F18: Cutting tube | I18: 0.01 | K18: cm | M18: 19.88 | O18: Material - Steel | Q18: 3 | S18: =I18*M18*Q18 -> 0.5964
Q19: Sub Total | S19: =SUM(S17:T18) -> 1.8964
A21: Item Order | C21: Fastener | F21: Use | I21: Unit Cost | K21: Size ( 1 ) | M21: Unit ( 1 ) | O21: Size ( 2 ) | Q21: Unit ( 2 ) | S21: Quantity | U21: Sub Total
S24: Sub Total
A26: Item Order | C26: Tooling | F26: Use | I26: Unit Cost | K26: Unit | M26: Quantity | O26: PVF | Q26: Frac Incld. | S26: Sub Total
Q29: Sub Total

Sheet FR 00202-AA
A1: University | C1: King Mongkut's University of Techonology Thonburi | L1: Car # | N1: EV-02 | T1: Part Cost | V1: =AA14+S19+U24+S29 -> 2.809
A2: System | C2: FR | T2: Qty | V2: 1
A3: Assembly | C3: Frame Assembly | L3: Filelink1
A4: Part | C4: Frame tube 2 | L4: Filelink 2 | T4: Extended Cost | V4: =V1*V2 -> 2.809
A5: P/N Base | C5: 00202 | L5: Filelink 3
A6: Suffix | C6: AA
A7: Details
A11: Item Order | C11: Material | F11: Use | I11: Unit Cost | K11: Size ( 1 ) | M11: Unit ( 1 ) | O11: Size ( 2 ) | Q11: Unit ( 2 ) | S11: Area Name | U11: Area | V11: Length | W11: Density | Y11: Quantity | AA11: Sub Total
A12: 1 | C12: Tubing, Steel | F12: Frame tube | I12: 2.25 | K12: 0.32 | M12: kg | O12: - | Q12: - | S12: Circle | U12: 91.27 mm^2 | V12: 442.32 mm | W12: - | Y12: 1 | AA12: =I12*K12*Y12 -> 0.72
Y14: Sub Total | AA14: =SUM(AA12:AB13) -> 0.72
A16: Item Order | C16: Process | F16: Use | I16: Unit Cost | K16: Unit | M16: Quantity | O16: Multiplier | Q16: Mult. Val. | S16: Sub Total
A17: 1 | C17: Machining Setup, Install and remove | F17: Setup the laser cut machine | I17: 1.3 | K17: Unit | M17: 1 | O17: - | Q17: 1 | S17: =I17*M17*Q17 -> 1.3
A18: 2 | C18: Laser Cut | F18: Cutting tube | I18: 0.01 | K18: cm | M18: 26.3 | O18: Material - Steel | Q18: 3 | S18: =I18*M18*Q18 -> 0.789
Q19: Sub Total | S19: =SUM(S17:T18) -> 2.089
A21: Item Order | C21: Fastener | F21: Use | I21: Unit Cost | K21: Size ( 1 ) | M21: Unit ( 1 ) | O21: Size ( 2 ) | Q21: Unit ( 2 ) | S21: Quantity | U21: Sub Total
S24: Sub Total
A26: Item Order | C26: Tooling | F26: Use | I26: Unit Cost | K26: Unit | M26: Quantity | O26: PVF | Q26: Frac Incld. | S26: Sub Total
Q29: Sub Total

Sheet FR 00203-AA
A1: University | C1: King Mongkut's University of Techonology Thonburi | L1: Car # | N1: EV-02 | T1: Part Cost | V1: =AA14+S19+U24+S29 -> 3.9727
A2: System | C2: FR | T2: Qty | V2: 1
A3: Assembly | C3: Frame Assembly | L3: Filelink1
A4: Part | C4: Front Hoop Bracing 1 | L4: Filelink 2 | T4: Extended Cost | V4: =V1*V2 -> 3.9727
A5: P/N Base | C5: 00203 | L5: Filelink 3
A6: Suffix | C6: AA
A7: Details
A11: Item Order | C11: Material | F11: Use | I11: Unit Cost | K11: Size ( 1 ) | M11: Unit ( 1 ) | O11: Size ( 2 ) | Q11: Unit ( 2 ) | S11: Area Name | U11: Area | V11: Length | W11: Density | Y11: Quantity | AA11: Sub Total
A12: 1 | C12: Tubing, Steel | F12: Front Hoop Bracing | I12: 2.25 | K12: 0.85 | M12: kg | O12: - | Q12: - | S12: Circle | U12: 119.68 mm^2 | V12: 906.25 mm | W12: - | Y12: 1 | AA12: =I12*K12*Y12 -> 1.9125
Y14: Sub Total | AA14: =SUM(AA12:AB13) -> 1.9125
A16: Item Order | C16: Process | F16: Use | I16: Unit Cost | K16: Unit | M16: Quantity | O16: Multiplier | Q16: Mult. Val. | S16: Sub Total
A17: 1 | C17: Machining Setup, Install and remove | F17: Setup the laser cut machine | I17: 1.3 | K17: Unit | M17: 1 | O17: - | Q17: 1 | S17: =I17*M17*Q17 -> 1.3
A18: 2 | C18: Laser Cut | F18: Cutting tube | I18: 0.01 | K18: cm | M18: 25.34 | O18: Material - Steel | Q18: 3 | S18: =I18*M18*Q18 -> 0.7602
Q19: Sub Total | S19: =SUM(S17:T18) -> 2.0602
A21: Item Order | C21: Fastener | F21: Use | I21: Unit Cost | K21: Size ( 1 ) | M21: Unit ( 1 ) | O21: Size ( 2 ) | Q21: Unit ( 2 ) | S21: Quantity | U21: Sub Total
S24: Sub Total
A26: Item Order | C26: Tooling | F26: Use | I26: Unit Cost | K26: Unit | M26: Quantity | O26: PVF | Q26: Frac Incld. | S26: Sub Total
Q29: Sub Total

Sheet FR 00204-AA
A1: University | C1: King Mongkut's University of Techonology Thonburi | L1: Car # | N1: EV-02 | T1: Part Cost | V1: =AA14+S19+U24+S29 -> 2.1166
A2: System | C2: FR | T2: Qty | V2: 1
A3: Assembly | C3: Frame Assembly | L3: Filelink1
A4: Part | C4: Frame tube 3 | L4: Filelink 2 | T4: Extended Cost | V4: =V1*V2 -> 2.1166
A5: P/N Base | C5: 00204 | L5: Filelink 3
A6: Suffix | C6: AA
A7: Details
A11: Item Order | C11: Material | F11: Use | I11: Unit Cost | K11: Size ( 1 ) | M11: Unit ( 1 ) | O11: Size ( 2 ) | Q11: Unit ( 2 ) | S11: Area Name | U11: Area | V11: Length | W11: Density | Y11: Quantity | AA11: Sub Total
A12: 1 | C12: Tubing, Steel | F12: Frame tube | I12: 2.25 | K12: 0.15 | M12: kg | O12: - | Q12: - | S12: Circle | U12: 91.27 mm^2 | V12: 205 mm | W12: - | Y12: 1 | AA12: =I12*K12*Y12 -> 0.3375
Y14: Sub Total | AA14: =SUM(AA12:AB13) -> 0.3375
A16: Item Order | C16: Process | F16: Use | I16: Unit Cost | K16: Unit | M16: Quantity | O16: Multiplier | Q16: Mult. Val. | S16: Sub Total
A17: 1 | C17: Machining Setup, Install and remove | F17: Setup the laser cut machine | I17: 1.3 | K17: Unit | M17: 1 | O17: - | Q17: 1 | S17: =I17*M17*Q17 -> 1.3
A18: 2 | C18: Laser Cut | F18: Cutting tube | I18: 0.01 | K18: cm | M18: 15.97 | O18: Material - Steel | Q18: 3 | S18: =I18*M18*Q18 -> 0.4791
Q19: Sub Total | S19: =SUM(S17:T18) -> 1.7791
A21: Item Order | C21: Fastener | F21: Use | I21: Unit Cost | K21: Size ( 1 ) | M21: Unit ( 1 ) | O21: Size ( 2 ) | Q21: Unit ( 2 ) | S21: Quantity | U21: Sub Total
S24: Sub Total
A26: Item Order | C26: Tooling | F26: Use | I26: Unit Cost | K26: Unit | M26: Quantity | O26: PVF | Q26: Frac Incld. | S26: Sub Total
Q29: Sub Total

Sheet FR 00205-AA
A1: University | C1: King Mongkut's University of Techonology Thonburi | L1: Car # | N1: EV-02 | T1: Part Cost | V1: =AA14+S19+U24+S29 -> 3.3367
A2: System | C2: FR | T2: Qty | V2: 1
A3: Assembly | C3: Frame Assembly | L3: Filelink1
A4: Part | C4: Frame tube 4 | L4: Filelink 2 | T4: Extended Cost | V4: =V1*V2 -> 3.3367
A5: P/N Base | C5: 00205 | L5: Filelink 3
A6: Suffix | C6: AA
A7: Details
A11: Item Order | C11: Material | F11: Use | I11: Unit Cost | K11: Size ( 1 ) | M11: Unit ( 1 ) | O11: Size ( 2 ) | Q11: Unit ( 2 ) | S11: Area Name | U11: Area | V11: Length | W11: Density | Y11: Quantity | AA11: Sub Total
A12: 1 | C12: Tubing, Steel | F12: Frame tube | I12: 2.25 | K12: 0.45 | M12: kg | O12: - | Q12: - | S12: Circle | U12: 91.27 mm^2 | V12: 626.71 mm | W12: - | Y12: 1 | AA12: =I12*K12*Y12 -> 1.0125
Y14: Sub Total | AA14: =SUM(AA12:AB13) -> 1.0125
A16: Item Order | C16: Process | F16: Use | I16: Unit Cost | K16: Unit | M16: Quantity | O16: Multiplier | Q16: Mult. Val. | S16: Sub Total
A17: 1 | C17: Machining Setup, Install and remove | F17: Setup the laser cut machine | I17: 1.3 | K17: Unit | M17: 1 | O17: - | Q17: 1 | S17: =I17*M17*Q17 -> 1.3
A18: 2 | C18: Laser Cut | F18: Cutting tube | I18: 0.01 | K18: cm | M18: 34.14 | O18: Material - Steel | Q18: 3 | S18: =I18*M18*Q18 -> 1.0242
Q19: Sub Total | S19: =SUM(S17:T18) -> 2.3242
A21: Item Order | C21: Fastener | F21: Use | I21: Unit Cost | K21: Size ( 1 ) | M21: Unit ( 1 ) | O21: Size ( 2 ) | Q21: Unit ( 2 ) | S21: Quantity | U21: Sub Total
S24: Sub Total
A26: Item Order | C26: Tooling | F26: Use | I26: Unit Cost | K26: Unit | M26: Quantity | O26: PVF | Q26: Frac Incld. | S26: Sub Total
Q29: Sub Total

Sheet FR 00206-AA
A1: University | C1: King Mongkut's University of Techonology Thonburi | L1: Car # | N1: EV-02 | T1: Part Cost | V1: =AA14+S19+U24+S29 -> 3.0496
A2: System | C2: FR | T2: Qty | V2: 1
A3: Assembly | C3: Frame Assembly | L3: Filelink1
A4: Part | C4: Frame tube 5 | L4: Filelink 2 | T4: Extended Cost | V4: =V1*V2 -> 3.0496
A5: P/N Base | C5: 00206 | L5: Filelink 3
A6: Suffix | C6: AA
A7: Details
A11: Item Order | C11: Material | F11: Use | I11: Unit Cost | K11: Size ( 1 ) | M11: Unit ( 1 ) | O11: Size ( 2 ) | Q11: Unit ( 2 ) | S11: Area Name | U11: Area | V11: Length | W11: Density | Y11: Quantity | AA11: Sub Total
A12: 1 | C12: Tubing, Steel | F12: Frame tube | I12: 2.25 | K12: 0.47 | M12: kg | O12: - | Q12: - | S12: Circle | U12: 91.27 mm^2 | V12: 651.88 mm | W12: - | Y12: 1 | AA12: =I12*K12*Y12 -> 1.0575
Y14: Sub Total | AA14: =SUM(AA12:AB13) -> 1.0575
A16: Item Order | C16: Process | F16: Use | I16: Unit Cost | K16: Unit | M16: Quantity | O16: Multiplier | Q16: Mult. Val. | S16: Sub Total
A17: 1 | C17: Machining Setup, Install and remove | F17: Setup the laser cut machine | I17: 1.3 | K17: Unit | M17: 1 | O17: - | Q17: 1 | S17: =I17*M17*Q17 -> 1.3
A18: 2 | C18: Laser Cut | F18: Cutting tube | I18: 0.01 | K18: cm | M18: 23.07 | O18: Material - Steel | Q18: 3 | S18: =I18*M18*Q18 -> 0.6921
Q19: Sub Total | S19: =SUM(S17:T18) -> 1.9921
A21: Item Order | C21: Fastener | F21: Use | I21: Unit Cost | K21: Size ( 1 ) | M21: Unit ( 1 ) | O21: Size ( 2 ) | Q21: Unit ( 2 ) | S21: Quantity | U21: Sub Total
S24: Sub Total
A26: Item Order | C26: Tooling | F26: Use | I26: Unit Cost | K26: Unit | M26: Quantity | O26: PVF | Q26: Frac Incld. | S26: Sub Total
Q29: Sub Total

Sheet FR 00207-AA
A1: University | C1: King Mongkut's University of Techonology Thonburi | L1: Car # | N1: EV-02 | T1: Part Cost | V1: =AA14+S19+U24+S29 -> 3.8891
A2: System | C2: FR | T2: Qty | V2: 1
A3: Assembly | C3: Frame Assembly | L3: Filelink1
A4: Part | C4: Front bulkhead tube 1 | L4: Filelink 2 | T4: Extended Cost | V4: =V1*V2 -> 3.8891
A5: P/N Base | C5: 00207 | L5: Filelink 3
A6: Suffix | C6: AA
A7: Details
A11: Item Order | C11: Material | F11: Use | I11: Unit Cost | K11: Size ( 1 ) | M11: Unit ( 1 ) | O11: Size ( 2 ) | Q11: Unit ( 2 ) | S11: Area Name | U11: Area | V11: Length | W11: Density | Y11: Quantity | AA11: Sub Total
A12: 1 | C12: Tubing, Steel | F12: Front bulkhead tube | I12: 2.25 | K12: 0.36 | M12: kg | O12: - | Q12: - | S12: Circle | U12: 119.68 mm^2 | V12: 390 mm | W12: - | Y12: 1 | AA12: =I12*K12*Y12 -> 0.81
Y14: Sub Total | AA14: =SUM(AA12:AB13) -> 0.81
A16: Item Order | C16: Process | F16: Use | I16: Unit Cost | K16: Unit | M16: Quantity | O16: Multiplier | Q16: Mult. Val. | S16: Sub Total
A17: 1 | C17: Machining Setup, Install and remove | F17: Setup the laser cut machine | I17: 1.3 | K17: Unit | M17: 2 | O17: - | Q17: 1 | S17: =I17*M17*Q17 -> 2.6
A18: 2 | C18: Laser Cut | F18: Cutting tube | I18: 0.01 | K18: cm | M18: 15.97 | O18: Material - Steel | Q18: 3 | S18: =I18*M18*Q18 -> 0.4791
Q19: Sub Total | S19: =SUM(S17:T18) -> 3.0791
A21: Item Order | C21: Fastener | F21: Use | I21: Unit Cost | K21: Size ( 1 ) | M21: Unit ( 1 ) | O21: Size ( 2 ) | Q21: Unit ( 2 ) | S21: Quantity | U21: Sub Total
S24: Sub Total
A26: Item Order | C26: Tooling | F26: Use | I26: Unit Cost | K26: Unit | M26: Quantity | O26: PVF | Q26: Frac Incld. | S26: Sub Total
Q29: Sub Total

Sheet FR 00208-AA
A1: University | C1: King Mongkut's University of Techonology Thonburi | L1: Car # | N1: EV-02 | T1: Part Cost | V1: =AA14+S19+U24+S29 -> 3.9473
A2: System | C2: FR | T2: Qty | V2: 1
A3: Assembly | C3: Frame Assembly | L3: Filelink1
A4: Part | C4: Front bulkhead tube 2 | L4: Filelink 2 | T4: Extended Cost | V4: =V1*V2 -> 3.9473
A5: P/N Base | C5: 00208 | L5: Filelink 3
A6: Suffix | C6: AA
A7: Details
A11: Item Order | C11: Material | F11: Use | I11: Unit Cost | K11: Size ( 1 ) | M11: Unit ( 1 ) | O11: Size ( 2 ) | Q11: Unit ( 2 ) | S11: Area Name | U11: Area | V11: Length | W11: Density | Y11: Quantity | AA11: Sub Total
A12: 1 | C12: Tubing, Steel | F12: Front bulkhead tube | I12: 2.25 | K12: 0.34 | M12: kg | O12: - | Q12: - | S12: Circle | U12: 119.68 mm^2 | V12: 360 mm | W12: - | Y12: 1 | AA12: =I12*K12*Y12 -> 0.765
Y14: Sub Total | AA14: =SUM(AA12:AB13) -> 0.765
A16: Item Order | C16: Process | F16: Use | I16: Unit Cost | K16: Unit | M16: Quantity | O16: Multiplier | Q16: Mult. Val. | S16: Sub Total
A17: 1 | C17: Machining Setup, Install and remove | F17: Setup the laser cut machine | I17: 1.3 | K17: Unit | M17: 2 | O17: - | Q17: 1 | S17: =I17*M17*Q17 -> 2.6
A18: 2 | C18: Laser Cut | F18: Cutting tube | I18: 0.01 | K18: cm | M18: 19.41 | O18: Material - Steel | Q18: 3 | S18: =I18*M18*Q18 -> 0.5823
Q19: Sub Total | S19: =SUM(S17:T18) -> 3.1823
A21: Item Order | C21: Fastener | F21: Use | I21: Unit Cost | K21: Size ( 1 ) | M21: Unit ( 1 ) | O21: Size ( 2 ) | Q21: Unit ( 2 ) | S21: Quantity | U21: Sub Total
S24: Sub Total
A26: Item Order | C26: Tooling | F26: Use | I26: Unit Cost | K26: Unit | M26: Quantity | O26: PVF | Q26: Frac Incld. | S26: Sub Total
Q29: Sub Total

Sheet FR 00209-AA
A1: University | C1: King Mongkut's University of Techonology Thonburi | L1: Car # | N1: EV-02 | T1: Part Cost | V1: =AA14+S19+U24+S29 -> 4.2218
A2: System | C2: FR | T2: Qty | V2: 1
A3: Assembly | C3: Frame Assembly | L3: Filelink1
A4: Part | C4: Front bulkhead tube 3 | L4: Filelink 2 | T4: Extended Cost | V4: =V1*V2 -> 4.2218
A5: P/N Base | C5: 00209 | L5: Filelink 3
A6: Suffix | C6: AA
A7: Details
A11: Item Order | C11: Material | F11: Use | I11: Unit Cost | K11: Size ( 1 ) | M11: Unit ( 1 ) | O11: Size ( 2 ) | Q11: Unit ( 2 ) | S11: Area Name | U11: Area | V11: Length | W11: Density | Y11: Quantity | AA11: Sub Total
A12: 1 | C12: Tubing, Steel | F12: Front bulkhead tube | I12: 2.25 | K12: 0.36 | M12: kg | O12: - | Q12: - | S12: Circle | U12: 91.27 mm^2 | V12: 509.12 mm | W12: - | Y12: 1 | AA12: =I12*K12*Y12 -> 0.81
Y14: Sub Total | AA14: =SUM(AA12:AB13) -> 0.81
A16: Item Order | C16: Process | F16: Use | I16: Unit Cost | K16: Unit | M16: Quantity | O16: Multiplier | Q16: Mult. Val. | S16: Sub Total
A17: 1 | C17: Machining Setup, Install and remove | F17: Setup the laser cut machine | I17: 1.3 | K17: Unit | M17: 2 | O17: - | Q17: 1 | S17: =I17*M17*Q17 -> 2.6
A18: 2 | C18: Laser Cut | F18: Cutting tube | I18: 0.01 | K18: cm | M18: 27.06 | O18: Material - Steel | Q18: 3 | S18: =I18*M18*Q18 -> 0.8118
Q19: Sub Total | S19: =SUM(S17:T18) -> 3.4118
A21: Item Order | C21: Fastener | F21: Use | I21: Unit Cost | K21: Size ( 1 ) | M21: Unit ( 1 ) | O21: Size ( 2 ) | Q21: Unit ( 2 ) | S21: Quantity | U21: Sub Total
S24: Sub Total
A26: Item Order | C26: Tooling | F26: Use | I26: Unit Cost | K26: Unit | M26: Quantity | O26: PVF | Q26: Frac Incld. | S26: Sub Total
Q29: Sub Total

Sheet FR 00210-AA
A1: University | C1: King Mongkut's University of Techonology Thonburi | L1: Car # | N1: EV-02 | T1: Part Cost | V1: =AA14+S19+U24+S29 -> 3.8891
A2: System | C2: FR | T2: Qty | V2: 1
A3: Assembly | C3: Frame Assembly | L3: Filelink1
A4: Part | C4: Front bulkhead tube 4 | L4: Filelink 2 | T4: Extended Cost | V4: =V1*V2 -> 3.8891
A5: P/N Base | C5: 00210 | L5: Filelink 3
A6: Suffix | C6: AA
A7: Details
A11: Item Order | C11: Material | F11: Use | I11: Unit Cost | K11: Size ( 1 ) | M11: Unit ( 1 ) | O11: Size ( 2 ) | Q11: Unit ( 2 ) | S11: Area Name | U11: Area | V11: Length | W11: Density | Y11: Quantity | AA11: Sub Total
A12: 1 | C12: Tubing, Steel | F12: Front bulkhead tube | I12: 2.25 | K12: 0.36 | M12: kg | O12: - | Q12: - | S12: Circle | U12: 119.68 mm^2 | V12: 390 mm | W12: - | Y12: 1 | AA12: =I12*K12*Y12 -> 0.81
Y14: Sub Total | AA14: =SUM(AA12:AB13) -> 0.81
A16: Item Order | C16: Process | F16: Use | I16: Unit Cost | K16: Unit | M16: Quantity | O16: Multiplier | Q16: Mult. Val. | S16: Sub Total
A17: 1 | C17: Machining Setup, Install and remove | F17: Setup the laser cut machine | I17: 1.3 | K17: Unit | M17: 2 | O17: - | Q17: 1 | S17: =I17*M17*Q17 -> 2.6
A18: 2 | C18: Laser Cut | F18: Cutting tube | I18: 0.01 | K18: cm | M18: 15.97 | O18: Material - Steel | Q18: 3 | S18: =I18*M18*Q18 -> 0.4791
Q19: Sub Total | S19: =SUM(S17:T18) -> 3.0791
A21: Item Order | C21: Fastener | F21: Use | I21: Unit Cost | K21: Size ( 1 ) | M21: Unit ( 1 ) | O21: Size ( 2 ) | Q21: Unit ( 2 ) | S21: Quantity | U21: Sub Total
S24: Sub Total
A26: Item Order | C26: Tooling | F26: Use | I26: Unit Cost | K26: Unit | M26: Quantity | O26: PVF | Q26: Frac Incld. | S26: Sub Total
Q29: Sub Total

Sheet FR 00211-AA
A1: University | C1: King Mongkut's University of Techonology Thonburi | L1: Car # | N1: EV-02 | T1: Part Cost | V1: =AA14+S19+U24+S29 -> 3.9473
A2: System | C2: FR | T2: Qty | V2: 1
A3: Assembly | C3: Frame Assembly | L3: Filelink1
A4: Part | C4: Front bulkhead tube 5 | L4: Filelink 2 | T4: Extended Cost | V4: =V1*V2 -> 3.9473
A5: P/N Base | C5: 00211 | L5: Filelink 3
A6: Suffix | C6: AA
A7: Details
A11: Item Order | C11: Material | F11: Use | I11: Unit Cost | K11: Size ( 1 ) | M11: Unit ( 1 ) | O11: Size ( 2 ) | Q11: Unit ( 2 ) | S11: Area Name | U11: Area | V11: Length | W11: Density | Y11: Quantity | AA11: Sub Total
A12: 1 | C12: Tubing, Steel | F12: Front bulkhead tube | I12: 2.25 | K12: 0.34 | M12: kg | O12: - | Q12: - | S12: Circle | U12: 119.68 mm^2 | V12: 360 mm | W12: - | Y12: 1 | AA12: =I12*K12*Y12 -> 0.765
Y14: Sub Total | AA14: =SUM(AA12:AB13) -> 0.765
A16: Item Order | C16: Process | F16: Use | I16: Unit Cost | K16: Unit | M16: Quantity | O16: Multiplier | Q16: Mult. Val. | S16: Sub Total
A17: 1 | C17: Machining Setup, Install and remove | F17: Setup the laser cut machine | I17: 1.3 | K17: Unit | M17: 2 | O17: - | Q17: 1 | S17: =I17*M17*Q17 -> 2.6
A18: 2 | C18: Laser Cut | F18: Cutting tube | I18: 0.01 | K18: cm | M18: 19.41 | O18: Material - Steel | Q18: 3 | S18: =I18*M18*Q18 -> 0.5823
Q19: Sub Total | S19: =SUM(S17:T18) -> 3.1823
A21: Item Order | C21: Fastener | F21: Use | I21: Unit Cost | K21: Size ( 1 ) | M21: Unit ( 1 ) | O21: Size ( 2 ) | Q21: Unit ( 2 ) | S21: Quantity | U21: Sub Total
S24: Sub Total
A26: Item Order | C26: Tooling | F26: Use | I26: Unit Cost | K26: Unit | M26: Quantity | O26: PVF | Q26: Frac Incld. | S26: Sub Total
Q29: Sub Total

Sheet FR 00212-AA
A1: University | C1: King Mongkut's University of Techonology Thonburi | L1: Car # | N1: EV-02 | T1: Part Cost | V1: =AA14+S19+U24+S29 -> 4.4588
A2: System | C2: FR | T2: Qty | V2: 1
A3: Assembly | C3: Frame Assembly | L3: Filelink1
A4: Part | C4: Frame Tube 6 | L4: Filelink 2 | T4: Extended Cost | V4: =V1*V2 -> 4.4588
A5: P/N Base | C5: 00212 | L5: Filelink 3
A6: Suffix | C6: AA
A7: Details
A11: Item Order | C11: Material | F11: Use | I11: Unit Cost | K11: Size ( 1 ) | M11: Unit ( 1 ) | O11: Size ( 2 ) | Q11: Unit ( 2 ) | S11: Area Name | U11: Area | V11: Length | W11: Density | Y11: Quantity | AA11: Sub Total
A12: 1 | C12: Tubing, Steel | F12: Frame tube | I12: 2.25 | K12: 0.58 | M12: kg | O12: - | Q12: - | S12: Circle | U12: 119.68 mm^2 | V12: 620.32 mm | W12: - | Y12: 1 | AA12: =I12*K12*Y12 -> 1.305
Y14: Sub Total | AA14: =SUM(AA12:AB13) -> 1.305
A16: Item Order | C16: Process | F16: Use | I16: Unit Cost | K16: Unit | M16: Quantity | O16: Multiplier | Q16: Mult. Val. | S16: Sub Total
A17: 1 | C17: Machining Setup, Install and remove | F17: Setup the laser cut machine | I17: 1.3 | K17: Unit | M17: 2 | O17: - | Q17: 1 | S17: =I17*M17*Q17 -> 2.6
A18: 2 | C18: Laser Cut | F18: Cutting tube | I18: 0.01 | K18: cm | M18: 18.46 | O18: Material - Steel | Q18: 3 | S18: =I18*M18*Q18 -> 0.5538
Q19: Sub Total | S19: =SUM(S17:T18) -> 3.1538
A21: Item Order | C21: Fastener | F21: Use | I21: Unit Cost | K21: Size ( 1 ) | M21: Unit ( 1 ) | O21: Size ( 2 ) | Q21: Unit ( 2 ) | S21: Quantity | U21: Sub Total
S24: Sub Total
A26: Item Order | C26: Tooling | F26: Use | I26: Unit Cost | K26: Unit | M26: Quantity | O26: PVF | Q26: Frac Incld. | S26: Sub Total
Q29: Sub Total

Sheet FR 00213-AA
A1: University | C1: King Mongkut's University of Techonology Thonburi | L1: Car # | N1: EV-02 | T1: Part Cost | V1: =AA14+S19+U24+S29 -> 2.1688
A2: System | C2: FR | T2: Qty | V2: 1
A3: Assembly | C3: Frame Assembly | L3: Filelink1
A4: Part | C4: Frame Tube 7 | L4: Filelink 2 | T4: Extended Cost | V4: =V1*V2 -> 2.1688
A5: P/N Base | C5: 00213 | L5: Filelink 3
A6: Suffix | C6: AA
A7: Details
A11: Item Order | C11: Material | F11: Use | I11: Unit Cost | K11: Size ( 1 ) | M11: Unit ( 1 ) | O11: Size ( 2 ) | Q11: Unit ( 2 ) | S11: Area Name | U11: Area | V11: Length | W11: Density | Y11: Quantity | AA11: Sub Total
A12: 1 | C12: Tubing, Steel | F12: Frame tube | I12: 2.25 | K12: 0.14 | M12: kg | O12: - | Q12: - | S12: Circle | U12: 61.85 mm^2 | V12: 280.1 mm | W12: - | Y12: 1 | AA12: =I12*K12*Y12 -> 0.315
Y14: Sub Total | AA14: =SUM(AA12:AB13) -> 0.315
A16: Item Order | C16: Process | F16: Use | I16: Unit Cost | K16: Unit | M16: Quantity | O16: Multiplier | Q16: Mult. Val. | S16: Sub Total
A17: 1 | C17: Machining Setup, Install and remove | F17: Setup the laser cut machine | I17: 1.3 | K17: Unit | M17: 1 | O17: - | Q17: 1 | S17: =I17*M17*Q17 -> 1.3
A18: 2 | C18: Laser Cut | F18: Cutting tube | I18: 0.01 | K18: cm | M18: 18.46 | O18: Material - Steel | Q18: 3 | S18: =I18*M18*Q18 -> 0.5538
Q19: Sub Total | S19: =SUM(S17:T18) -> 1.8538
A21: Item Order | C21: Fastener | F21: Use | I21: Unit Cost | K21: Size ( 1 ) | M21: Unit ( 1 ) | O21: Size ( 2 ) | Q21: Unit ( 2 ) | S21: Quantity | U21: Sub Total
S24: Sub Total
A26: Item Order | C26: Tooling | F26: Use | I26: Unit Cost | K26: Unit | M26: Quantity | O26: PVF | Q26: Frac Incld. | S26: Sub Total
Q29: Sub Total

Sheet FR 00214-AA
A1: University | C1: King Mongkut's University of Techonology Thonburi | L1: Car # | N1: EV-02 | T1: Part Cost | V1: =AA14+S20+U25+S30 -> 9.079
A2: System | C2: FR | T2: Qty | V2: 1
A3: Assembly | C3: Frame Assembly | L3: Filelink1
A4: Part | C4: Front Hoop | L4: Filelink 2 | T4: Extended Cost | V4: =V1*V2 -> 9.079
A5: P/N Base | C5: 00214 | L5: Filelink 3
A6: Suffix | C6: AA
A7: Details
A11: Item Order | C11: Material | F11: Use | I11: Unit Cost | K11: Size ( 1 ) | M11: Unit ( 1 ) | O11: Size ( 2 ) | Q11: Unit ( 2 ) | S11: Area Name | U11: Area | V11: Length | W11: Density | Y11: Quantity | AA11: Sub Total
A12: 1 | C12: Tubing, Steel | F12: Front Hoop | I12: 2.25 | K12: 2.124 | M12: kg | O12: - | Q12: - | S12: Circle | U12: 173.49 mm^2 | V12: 957.93 mm | W12: - | Y12: 1 | AA12: =I12*K12*Y12 -> 4.779
Y14: Sub Total | AA14: =SUM(AA12:AB13) -> 4.779
A16: Item Order | C16: Process | F16: Use | I16: Unit Cost | K16: Unit | M16: Quantity | O16: Multiplier | Q16: Mult. Val. | S16: Sub Total
A17: 1 | C17: Machining Setup, Install and remove | F17: Setup the laser cut machine | I17: 1.3 | K17: Unit | M17: 1 | O17: - | Q17: 1 | S17: =I17*M17*Q17 -> 1.3
A18: 2 | C18: Laser Cut | F18: Cutting tube | I18: 0.01 | K18: cm | O18: Material - Steel | Q18: 3 | S18: =I18*M18*Q18 -> 0
A19: 3 | C19: Tube bends | F19: Front Hoop bend | I19: 0.75 | K19: bend | M19: 4 | O19: - | Q19: 1 | S19: =I19*M19*Q19 -> 3
Q20: Sub Total | S20: =SUM(S19:T19,S18:T18,S17:T17) -> 4.3
A22: Item Order | C22: Fastener | F22: Use | I22: Unit Cost | K22: Size ( 1 ) | M22: Unit ( 1 ) | O22: Size ( 2 ) | Q22: Unit ( 2 ) | S22: Quantity | U22: Sub Total
S25: Sub Total
A27: Item Order | C27: Tooling | F27: Use | I27: Unit Cost | K27: Unit | M27: Quantity | O27: PVF | Q27: Frac Incld. | S27: Sub Total
Q30: Sub Total

Sheet FR 00215-AA
A1: University | C1: King Mongkut's University of Techonology Thonburi | L1: Car # | N1: EV-02 | T1: Part Cost | V1: =AA14+S19+U24+S29 -> 3.9727
A2: System | C2: FR | T2: Qty | V2: 1
A3: Assembly | C3: Frame Assembly | L3: Filelink1
A4: Part | C4: Front Hoop Bracing 2 | L4: Filelink 2 | T4: Extended Cost | V4: =V1*V2 -> 3.9727
A5: P/N Base | C5: 00215 | L5: Filelink 3
A6: Suffix | C6: AA
A7: Details
A11: Item Order | C11: Material | F11: Use | I11: Unit Cost | K11: Size ( 1 ) | M11: Unit ( 1 ) | O11: Size ( 2 ) | Q11: Unit ( 2 ) | S11: Area Name | U11: Area | V11: Length | W11: Density | Y11: Quantity | AA11: Sub Total
A12: 1 | C12: Tubing, Steel | F12: Front Hoop Bracing | I12: 2.25 | K12: 0.85 | M12: kg | O12: - | Q12: - | S12: Circle | U12: 119.68 mm^2 | V12: 906.25 mm | W12: - | Y12: 1 | AA12: =I12*K12*Y12 -> 1.9125
Y14: Sub Total | AA14: =SUM(AA12:AB13) -> 1.9125
A16: Item Order | C16: Process | F16: Use | I16: Unit Cost | K16: Unit | M16: Quantity | O16: Multiplier | Q16: Mult. Val. | S16: Sub Total
A17: 1 | C17: Machining Setup, Install and remove | F17: Setup the laser cut machine | I17: 1.3 | K17: Unit | M17: 1 | O17: - | Q17: 1 | S17: =I17*M17*Q17 -> 1.3
A18: 2 | C18: Laser Cut | F18: Cutting tube | I18: 0.01 | K18: cm | M18: 25.34 | O18: Material - Steel | Q18: 3 | S18: =I18*M18*Q18 -> 0.7602
Q19: Sub Total | S19: =SUM(S17:T18) -> 2.0602
A21: Item Order | C21: Fastener | F21: Use | I21: Unit Cost | K21: Size ( 1 ) | M21: Unit ( 1 ) | O21: Size ( 2 ) | Q21: Unit ( 2 ) | S21: Quantity | U21: Sub Total
S24: Sub Total
A26: Item Order | C26: Tooling | F26: Use | I26: Unit Cost | K26: Unit | M26: Quantity | O26: PVF | Q26: Frac Incld. | S26: Sub Total
Q29: Sub Total

Sheet FR 00216-AA
A1: University | C1: King Mongkut's University of Techonology Thonburi | L1: Car # | N1: EV-02 | T1: Part Cost | V1: =AA14+S19+U24+S29 -> 2.2474
A2: System | C2: FR | T2: Qty | V2: 1
A3: Assembly | C3: Frame Assembly | L3: Filelink1
A4: Part | C4: Frame tube 8 | L4: Filelink 2 | T4: Extended Cost | V4: =V1*V2 -> 2.2474
A5: P/N Base | C5: 00216 | L5: Filelink 3
A6: Suffix | C6: AA
A7: Details
A11: Item Order | C11: Material | F11: Use | I11: Unit Cost | K11: Size ( 1 ) | M11: Unit ( 1 ) | O11: Size ( 2 ) | Q11: Unit ( 2 ) | S11: Area Name | U11: Area | V11: Length | W11: Density | Y11: Quantity | AA11: Sub Total
A12: 1 | C12: Tubing, Steel | F12: Frame tube | I12: 2.25 | K12: 0.15 | M12: kg | O12: - | Q12: - | S12: Circle | U12: 61.85 mm^2 | V12: 305 mm | W12: - | Y12: 1 | AA12: =I12*K12*Y12 -> 0.3375
Y14: Sub Total | AA14: =SUM(AA12:AB13) -> 0.3375
A16: Item Order | C16: Process | F16: Use | I16: Unit Cost | K16: Unit | M16: Quantity | O16: Multiplier | Q16: Mult. Val. | S16: Sub Total
A17: 1 | C17: Machining Setup, Install and remove | F17: Setup the laser cut machine | I17: 1.3 | K17: Unit | M17: 1 | O17: - | Q17: 1 | S17: =I17*M17*Q17 -> 1.3
A18: 2 | C18: Laser Cut | F18: Cutting tube | I18: 0.01 | K18: cm | M18: 20.33 | O18: Material - Steel | Q18: 3 | S18: =I18*M18*Q18 -> 0.6099
Q19: Sub Total | S19: =SUM(S17:T18) -> 1.9099
A21: Item Order | C21: Fastener | F21: Use | I21: Unit Cost | K21: Size ( 1 ) | M21: Unit ( 1 ) | O21: Size ( 2 ) | Q21: Unit ( 2 ) | S21: Quantity | U21: Sub Total
S24: Sub Total
A26: Item Order | C26: Tooling | F26: Use | I26: Unit Cost | K26: Unit | M26: Quantity | O26: PVF | Q26: Frac Incld. | S26: Sub Total
Q29: Sub Total

Sheet FR 00217-AA
A1: University | C1: King Mongkut's University of Techonology Thonburi | L1: Car # | N1: EV-02 | T1: Part Cost | V1: =AA14+S19+U24+S29 -> 2.2699
A2: System | C2: FR | T2: Qty | V2: 1
A3: Assembly | C3: Frame Assembly | L3: Filelink1
A4: Part | C4: Frame tube 9 | L4: Filelink 2 | T4: Extended Cost | V4: =V1*V2 -> 2.2699
A5: P/N Base | C5: 00217 | L5: Filelink 3
A6: Suffix | C6: AA
A7: Details
A11: Item Order | C11: Material | F11: Use | I11: Unit Cost | K11: Size ( 1 ) | M11: Unit ( 1 ) | O11: Size ( 2 ) | Q11: Unit ( 2 ) | S11: Area Name | U11: Area | V11: Length | W11: Density | Y11: Quantity | AA11: Sub Total
A12: 1 | C12: Tubing, Steel | F12: Frame tube | I12: 2.25 | K12: 0.16 | M12: kg | O12: - | Q12: - | S12: Circle | U12: 61.85 mm^2 | V12: 320 mm | W12: - | Y12: 1 | AA12: =I12*K12*Y12 -> 0.36
Y14: Sub Total | AA14: =SUM(AA12:AB13) -> 0.36
A16: Item Order | C16: Process | F16: Use | I16: Unit Cost | K16: Unit | M16: Quantity | O16: Multiplier | Q16: Mult. Val. | S16: Sub Total
A17: 1 | C17: Machining Setup, Install and remove | F17: Setup the laser cut machine | I17: 1.3 | K17: Unit | M17: 1 | O17: - | Q17: 1 | S17: =I17*M17*Q17 -> 1.3
A18: 2 | C18: Laser Cut | F18: Cutting tube | I18: 0.01 | K18: cm | M18: 20.33 | O18: Material - Steel | Q18: 3 | S18: =I18*M18*Q18 -> 0.6099
Q19: Sub Total | S19: =SUM(S17:T18) -> 1.9099
A21: Item Order | C21: Fastener | F21: Use | I21: Unit Cost | K21: Size ( 1 ) | M21: Unit ( 1 ) | O21: Size ( 2 ) | Q21: Unit ( 2 ) | S21: Quantity | U21: Sub Total
S24: Sub Total
A26: Item Order | C26: Tooling | F26: Use | I26: Unit Cost | K26: Unit | M26: Quantity | O26: PVF | Q26: Frac Incld. | S26: Sub Total
Q29: Sub Total

Sheet FR 00218-AA
A1: University | C1: King Mongkut's University of Techonology Thonburi | L1: Car # | N1: EV-02 | T1: Part Cost | V1: =AA14+S19+U24+S29 -> 4.6286
A2: System | C2: FR | T2: Qty | V2: 1
A3: Assembly | C3: Frame Assembly | L3: Filelink1
A4: Part | C4: Frame tube 10 | L4: Filelink 2 | T4: Extended Cost | V4: =V1*V2 -> 4.6286
A5: P/N Base | C5: 00218 | L5: Filelink 3
A6: Suffix | C6: AA
A7: Details
A11: Item Order | C11: Material | F11: Use | I11: Unit Cost | K11: Size ( 1 ) | M11: Unit ( 1 ) | O11: Size ( 2 ) | Q11: Unit ( 2 ) | S11: Area Name | U11: Area | V11: Length | W11: Density | Y11: Quantity | AA11: Sub Total
A12: 1 | C12: Tubing, Steel | F12: Frame tube | I12: 2.25 | K12: 0.45 | M12: kg | O12: - | Q12: - | S12: Circle | U12: 91.27 mm^2 | V12: 626.08 mm | W12: - | Y12: 1 | AA12: =I12*K12*Y12 -> 1.0125
Y14: Sub Total | AA14: =SUM(AA12:AB13) -> 1.0125
A16: Item Order | C16: Process | F16: Use | I16: Unit Cost | K16: Unit | M16: Quantity | O16: Multiplier | Q16: Mult. Val. | S16: Sub Total
A17: 1 | C17: Machining Setup, Install and remove | F17: Setup the laser cut machine | I17: 1.3 | K17: Unit | M17: 2 | O17: - | Q17: 1 | S17: =I17*M17*Q17 -> 2.6
A18: 2 | C18: Laser Cut | F18: Cutting tube | I18: 0.01 | K18: cm | M18: 33.87 | O18: Material - Steel | Q18: 3 | S18: =I18*M18*Q18 -> 1.0161
Q19: Sub Total | S19: =SUM(S17:T18) -> 3.6161
A21: Item Order | C21: Fastener | F21: Use | I21: Unit Cost | K21: Size ( 1 ) | M21: Unit ( 1 ) | O21: Size ( 2 ) | Q21: Unit ( 2 ) | S21: Quantity | U21: Sub Total
S24: Sub Total
A26: Item Order | C26: Tooling | F26: Use | I26: Unit Cost | K26: Unit | M26: Quantity | O26: PVF | Q26: Frac Incld. | S26: Sub Total
Q29: Sub Total

Sheet FR 00219-AA
A1: University | C1: King Mongkut's University of Techonology Thonburi | L1: Car # | N1: EV-02 | T1: Part Cost | V1: =AA14+S19+U24+S29 -> 4.3568
A2: System | C2: FR | T2: Qty | V2: 1
A3: Assembly | C3: Frame Assembly | L3: Filelink1
A4: Part | C4: Frame tube 11 | L4: Filelink 2 | T4: Extended Cost | V4: =V1*V2 -> 4.3568
A5: P/N Base | C5: 00219 | L5: Filelink 3
A6: Suffix | C6: AA
A7: Details
A11: Item Order | C11: Material | F11: Use | I11: Unit Cost | K11: Size ( 1 ) | M11: Unit ( 1 ) | O11: Size ( 2 ) | Q11: Unit ( 2 ) | S11: Area Name | U11: Area | V11: Length | W11: Density | Y11: Quantity | AA11: Sub Total
A12: 1 | C12: Tubing, Steel | F12: Frame tube | I12: 2.25 | K12: 0.47 | M12: kg | O12: - | Q12: - | S12: Circle | U12: 91.27 mm^2 | V12: 653.98 mm | W12: - | Y12: 1 | AA12: =I12*K12*Y12 -> 1.0575
Y14: Sub Total | AA14: =SUM(AA12:AB13) -> 1.0575
A16: Item Order | C16: Process | F16: Use | I16: Unit Cost | K16: Unit | M16: Quantity | O16: Multiplier | Q16: Mult. Val. | S16: Sub Total
A17: 1 | C17: Machining Setup, Install and remove | F17: Setup the laser cut machine | I17: 1.3 | K17: Unit | M17: 2 | O17: - | Q17: 1 | S17: =I17*M17*Q17 -> 2.6
A18: 2 | C18: Laser Cut | F18: Cutting tube | I18: 0.01 | K18: cm | M18: 23.31 | O18: Material - Steel | Q18: 3 | S18: =I18*M18*Q18 -> 0.6993
Q19: Sub Total | S19: =SUM(S17:T18) -> 3.2993
A21: Item Order | C21: Fastener | F21: Use | I21: Unit Cost | K21: Size ( 1 ) | M21: Unit ( 1 ) | O21: Size ( 2 ) | Q21: Unit ( 2 ) | S21: Quantity | U21: Sub Total
S24: Sub Total
A26: Item Order | C26: Tooling | F26: Use | I26: Unit Cost | K26: Unit | M26: Quantity | O26: PVF | Q26: Frac Incld. | S26: Sub Total
Q29: Sub Total

Sheet FR 00220-AA
A1: University | C1: King Mongkut's University of Techonology Thonburi | L1: Car # | N1: EV-02 | T1: Part Cost | V1: =AA14+S19+U24+S29 -> 4.1384
A2: System | C2: FR | T2: Qty | V2: 1
A3: Assembly | C3: Frame Assembly | L3: Filelink1
A4: Part | C4: Frame tube 12 | L4: Filelink 2 | T4: Extended Cost | V4: =V1*V2 -> 4.1384
A5: P/N Base | C5: 00220 | L5: Filelink 3
A6: Suffix | C6: AA
A7: Details
A11: Item Order | C11: Material | F11: Use | I11: Unit Cost | K11: Size ( 1 ) | M11: Unit ( 1 ) | O11: Size ( 2 ) | Q11: Unit ( 2 ) | S11: Area Name | U11: Area | V11: Length | W11: Density | Y11: Quantity | AA11: Sub Total
A12: 1 | C12: Tubing, Steel | F12: Frame tube | I12: 2.25 | K12: 0.44 | M12: kg | O12: - | Q12: - | S12: Circle | U12: 91.27 mm^2 | V12: 620.32 mm | W12: - | Y12: 1 | AA12: =I12*K12*Y12 -> 0.99
Y14: Sub Total | AA14: =SUM(AA12:AB13) -> 0.99
A16: Item Order | C16: Process | F16: Use | I16: Unit Cost | K16: Unit | M16: Quantity | O16: Multiplier | Q16: Mult. Val. | S16: Sub Total
A17: 1 | C17: Machining Setup, Install and remove | F17: Setup the laser cut machine | I17: 1.3 | K17: Unit | M17: 2 | O17: - | Q17: 1 | S17: =I17*M17*Q17 -> 2.6
A18: 2 | C18: Laser Cut | F18: Cutting tube | I18: 0.01 | K18: cm | M18: 18.28 | O18: Material - Steel | Q18: 3 | S18: =I18*M18*Q18 -> 0.5484
Q19: Sub Total | S19: =SUM(S17:T18) -> 3.1484
A21: Item Order | C21: Fastener | F21: Use | I21: Unit Cost | K21: Size ( 1 ) | M21: Unit ( 1 ) | O21: Size ( 2 ) | Q21: Unit ( 2 ) | S21: Quantity | U21: Sub Total
S24: Sub Total
A26: Item Order | C26: Tooling | F26: Use | I26: Unit Cost | K26: Unit | M26: Quantity | O26: PVF | Q26: Frac Incld. | S26: Sub Total
Q29: Sub Total

Sheet FR 00221-AA
A1: University | C1: King Mongkut's University of Techonology Thonburi | L1: Car # | N1: EV-02 | T1: Part Cost | V1: =AA14+S19+U24+S29 -> 2.10985
A2: System | C2: FR | T2: Qty | V2: 1
A3: Assembly | C3: Frame Assembly | L3: Filelink1
A4: Part | C4: Frame tube 13 | L4: Filelink 2 | T4: Extended Cost | V4: =V1*V2 -> 2.10985
A5: P/N Base | C5: 00221 | L5: Filelink 3
A6: Suffix | C6: AA
A7: Details
A11: Item Order | C11: Material | F11: Use | I11: Unit Cost | K11: Size ( 1 ) | M11: Unit ( 1 ) | O11: Size ( 2 ) | Q11: Unit ( 2 ) | S11: Area Name | U11: Area | V11: Length | W11: Density | Y11: Quantity | AA11: Sub Total
A12: 1 | C12: Tubing, Steel | F12: Frame tube | I12: 2.25 | K12: 0.147 | M12: kg | O12: - | Q12: - | S12: Circle | U12: 91.27 mm^2 | V12: 205 mm | W12: - | Y12: 1 | AA12: =I12*K12*Y12 -> 0.33075
Y14: Sub Total | AA14: =SUM(AA12:AB13) -> 0.33075
A16: Item Order | C16: Process | F16: Use | I16: Unit Cost | K16: Unit | M16: Quantity | O16: Multiplier | Q16: Mult. Val. | S16: Sub Total
A17: 1 | C17: Machining Setup, Install and remove | F17: Setup the laser cut machine | I17: 1.3 | K17: Unit | M17: 1 | O17: - | Q17: 1 | S17: =I17*M17*Q17 -> 1.3
A18: 2 | C18: Laser Cut | F18: Cutting tube | I18: 0.01 | K18: cm | M18: 15.97 | O18: Material - Steel | Q18: 3 | S18: =I18*M18*Q18 -> 0.4791
Q19: Sub Total | S19: =SUM(S17:T18) -> 1.7791
A21: Item Order | C21: Fastener | F21: Use | I21: Unit Cost | K21: Size ( 1 ) | M21: Unit ( 1 ) | O21: Size ( 2 ) | Q21: Unit ( 2 ) | S21: Quantity | U21: Sub Total
S24: Sub Total
A26: Item Order | C26: Tooling | F26: Use | I26: Unit Cost | K26: Unit | M26: Quantity | O26: PVF | Q26: Frac Incld. | S26: Sub Total
Q29: Sub Total

Sheet FR 00222-AA
A1: University | C1: King Mongkut's University of Techonology Thonburi | L1: Car # | N1: EV-02 | T1: Part Cost | V1: =AA14+S19+U24+S29 -> 2.4388
A2: System | C2: FR | T2: Qty | V2: 1
A3: Assembly | C3: Frame Assembly | L3: Filelink1
A4: Part | C4: Frame tube 14 | L4: Filelink 2 | T4: Extended Cost | V4: =V1*V2 -> 2.4388
A5: P/N Base | C5: 00222 | L5: Filelink 3
A6: Suffix | C6: AA
A7: Details
A11: Item Order | C11: Material | F11: Use | I11: Unit Cost | K11: Size ( 1 ) | M11: Unit ( 1 ) | O11: Size ( 2 ) | Q11: Unit ( 2 ) | S11: Area Name | U11: Area | V11: Length | W11: Density | Y11: Quantity | AA11: Sub Total
A12: 1 | C12: Tubing, Steel | F12: Frame tube | I12: 2.25 | K12: 0.26 | M12: kg | O12: - | Q12: - | S12: Circle | U12: 119.68 mm^2 | V12: 280.1 mm | W12: - | Y12: 1 | AA12: =I12*K12*Y12 -> 0.585
Y14: Sub Total | AA14: =SUM(AA12:AB13) -> 0.585
A16: Item Order | C16: Process | F16: Use | I16: Unit Cost | K16: Unit | M16: Quantity | O16: Multiplier | Q16: Mult. Val. | S16: Sub Total
A17: 1 | C17: Machining Setup, Install and remove | F17: Setup the laser cut machine | I17: 1.3 | K17: Unit | M17: 1 | O17: - | Q17: 1 | S17: =I17*M17*Q17 -> 1.3
A18: 2 | C18: Laser Cut | F18: Cutting tube | I18: 0.01 | K18: cm | M18: 18.46 | O18: Material - Steel | Q18: 3 | S18: =I18*M18*Q18 -> 0.5538
Q19: Sub Total | S19: =SUM(S17:T18) -> 1.8538
A21: Item Order | C21: Fastener | F21: Use | I21: Unit Cost | K21: Size ( 1 ) | M21: Unit ( 1 ) | O21: Size ( 2 ) | Q21: Unit ( 2 ) | S21: Quantity | U21: Sub Total
S24: Sub Total
A26: Item Order | C26: Tooling | F26: Use | I26: Unit Cost | K26: Unit | M26: Quantity | O26: PVF | Q26: Frac Incld. | S26: Sub Total
Q29: Sub Total

Sheet FR 00223-AA
A1: University | C1: King Mongkut's University of Techonology Thonburi | L1: Car # | N1: EV-02 | T1: Part Cost | V1: =AA14+S19+U24+S29 -> 2.4103
A2: System | C2: FR | T2: Qty | V2: 1
A3: Assembly | C3: Frame Assembly | L3: Filelink1
A4: Part | C4: Frame tube 15 | L4: Filelink 2 | T4: Extended Cost | V4: =V1*V2 -> 2.4103
A5: P/N Base | C5: 00223 | L5: Filelink 3
A6: Suffix | C6: AA
A7: Details
A11: Item Order | C11: Material | F11: Use | I11: Unit Cost | K11: Size ( 1 ) | M11: Unit ( 1 ) | O11: Size ( 2 ) | Q11: Unit ( 2 ) | S11: Area Name | U11: Area | V11: Length | W11: Density | Y11: Quantity | AA11: Sub Total
A12: 1 | C12: Tubing, Steel | F12: Frame tube | I12: 2.25 | K12: 0.21 | M12: kg | O12: - | Q12: - | S12: Circle | U12: 91.27 mm^2 | V12: 293.23 mm | W12: - | Y12: 1 | AA12: =I12*K12*Y12 -> 0.4725
Y14: Sub Total | AA14: =SUM(AA12:AB13) -> 0.4725
A16: Item Order | C16: Process | F16: Use | I16: Unit Cost | K16: Unit | M16: Quantity | O16: Multiplier | Q16: Mult. Val. | S16: Sub Total
A17: 1 | C17: Machining Setup, Install and remove | F17: Setup the laser cut machine | I17: 1.3 | K17: Unit | M17: 1 | O17: - | Q17: 1 | S17: =I17*M17*Q17 -> 1.3
A18: 2 | C18: Laser Cut | F18: Cutting tube | I18: 0.01 | K18: cm | M18: 21.26 | O18: Material - Steel | Q18: 3 | S18: =I18*M18*Q18 -> 0.6378
Q19: Sub Total | S19: =SUM(S17:T18) -> 1.9378
A21: Item Order | C21: Fastener | F21: Use | I21: Unit Cost | K21: Size ( 1 ) | M21: Unit ( 1 ) | O21: Size ( 2 ) | Q21: Unit ( 2 ) | S21: Quantity | U21: Sub Total
S24: Sub Total
A26: Item Order | C26: Tooling | F26: Use | I26: Unit Cost | K26: Unit | M26: Quantity | O26: PVF | Q26: Frac Incld. | S26: Sub Total
Q29: Sub Total

Sheet FR 00224-AA
A1: University | C1: King Mongkut's University of Techonology Thonburi | L1: Car # | N1: EV-02 | T1: Part Cost | V1: =AA14+S19+U24+S29 -> 2.8201
A2: System | C2: FR | T2: Qty | V2: 1
A3: Assembly | C3: Frame Assembly | L3: Filelink1
A4: Part | C4: Frame tube 16 | L4: Filelink 2 | T4: Extended Cost | V4: =V1*V2 -> 2.8201
A5: P/N Base | C5: 00224 | L5: Filelink 3
A6: Suffix | C6: AA
A7: Details
A11: Item Order | C11: Material | F11: Use | I11: Unit Cost | K11: Size ( 1 ) | M11: Unit ( 1 ) | O11: Size ( 2 ) | Q11: Unit ( 2 ) | S11: Area Name | U11: Area | V11: Length | W11: Density | Y11: Quantity | AA11: Sub Total
A12: 1 | C12: Tubing, Steel | F12: Frame tube | I12: 2.25 | K12: 0.325 | M12: kg | O12: - | Q12: - | S12: Circle | U12: 91.27 mm^2 | V12: 453.70 mm | W12: - | Y12: 1 | AA12: =I12*K12*Y12 -> 0.73125
Y14: Sub Total | AA14: =SUM(AA12:AB13) -> 0.73125
A16: Item Order | C16: Process | F16: Use | I16: Unit Cost | K16: Unit | M16: Quantity | O16: Multiplier | Q16: Mult. Val. | S16: Sub Total
A17: 1 | C17: Machining Setup, Install and remove | F17: Setup the laser cut machine | I17: 1.3 | K17: Unit | M17: 1 | O17: - | Q17: 1 | S17: =I17*M17*Q17 -> 1.3
A18: 2 | C18: Laser Cut | F18: Cutting tube | I18: 0.01 | K18: cm | M18: 26.295 | O18: Material - Steel | Q18: 3 | S18: =I18*M18*Q18 -> 0.78885
Q19: Sub Total | S19: =SUM(S17:T18) -> 2.08885
A21: Item Order | C21: Fastener | F21: Use | I21: Unit Cost | K21: Size ( 1 ) | M21: Unit ( 1 ) | O21: Size ( 2 ) | Q21: Unit ( 2 ) | S21: Quantity | U21: Sub Total
S24: Sub Total
A26: Item Order | C26: Tooling | F26: Use | I26: Unit Cost | K26: Unit | M26: Quantity | O26: PVF | Q26: Frac Incld. | S26: Sub Total
Q29: Sub Total

Sheet FR 00225-AA
A1: University | C1: King Mongkut's University of Techonology Thonburi | L1: Car # | N1: EV-02 | T1: Part Cost | V1: =AA14+S19+U24+S29 -> 2.2285
A2: System | C2: FR | T2: Qty | V2: 1
A3: Assembly | C3: Frame Assembly | L3: Filelink1
A4: Part | C4: Sholder Hardness Braces 1 | L4: Filelink 2 | T4: Extended Cost | V4: =V1*V2 -> 2.2285
A5: P/N Base | C5: 00225 | L5: Filelink 3
A6: Suffix | C6: AA
A7: Details
A11: Item Order | C11: Material | F11: Use | I11: Unit Cost | K11: Size ( 1 ) | M11: Unit ( 1 ) | O11: Size ( 2 ) | Q11: Unit ( 2 ) | S11: Area Name | U11: Area | V11: Length | W11: Density | Y11: Quantity | AA11: Sub Total
A12: 1 | C12: Tubing, Steel | F12: Sholder Hardness Braces | I12: 2.25 | K12: 0.07 | M12: kg | O12: - | Q12: - | S12: Circle | U12: 91.27 mm^2 | V12: 102.4 mm | W12: - | Y12: 1 | AA12: =I12*K12*Y12 -> 0.1575
Y14: Sub Total | AA14: =SUM(AA12:AB13) -> 0.1575
A16: Item Order | C16: Process | F16: Use | I16: Unit Cost | K16: Unit | M16: Quantity | O16: Multiplier | Q16: Mult. Val. | S16: Sub Total
A17: 1 | C17: Machining Setup, Install and remove | F17: Setup the laser cut machine | I17: 1.3 | K17: Unit | M17: 1 | O17: - | Q17: 1 | S17: =I17*M17*Q17 -> 1.3
A18: 2 | C18: Laser Cut | F18: Cutting tube | I18: 0.01 | K18: cm | M18: 25.7 | O18: Material - Steel | Q18: 3 | S18: =I18*M18*Q18 -> 0.771
Q19: Sub Total | S19: =SUM(S17:T18) -> 2.071
A21: Item Order | C21: Fastener | F21: Use | I21: Unit Cost | K21: Size ( 1 ) | M21: Unit ( 1 ) | O21: Size ( 2 ) | Q21: Unit ( 2 ) | S21: Quantity | U21: Sub Total
S24: Sub Total
A26: Item Order | C26: Tooling | F26: Use | I26: Unit Cost | K26: Unit | M26: Quantity | O26: PVF | Q26: Frac Incld. | S26: Sub Total
Q29: Sub Total

Sheet FR 00226-AA
A1: University | C1: King Mongkut's University of Techonology Thonburi | L1: Car # | N1: EV-02 | T1: Part Cost | V1: =AA14+S20+U25+S30 -> 11.3863
A2: System | C2: FR | T2: Qty | V2: 1
A3: Assembly | C3: Frame Assembly | L3: Filelink1
A4: Part | C4: Main Hoop | L4: Filelink 2 | T4: Extended Cost | V4: =V1*V2 -> 11.3863
A5: P/N Base | C5: 00226 | L5: Filelink 3
A6: Suffix | C6: AA
A7: Details
A11: Item Order | C11: Material | F11: Use | I11: Unit Cost | K11: Size ( 1 ) | M11: Unit ( 1 ) | O11: Size ( 2 ) | Q11: Unit ( 2 ) | S11: Area Name | U11: Area | V11: Length | W11: Density | Y11: Quantity | AA11: Sub Total
A12: 1 | C12: Tubing, Steel | F12: Main Hoop | I12: 2.25 | K12: 3.29 | M12: kg | O12: - | Q12: - | S12: Circle | U12: 173.49 mm^2 | V12: 2415.48 mm | W12: - | Y12: 1 | AA12: =I12*K12*Y12 -> 7.4025
Y14: Sub Total | AA14: =SUM(AA12:AB13) -> 7.4025
A16: Item Order | C16: Process | F16: Use | I16: Unit Cost | K16: Unit | M16: Quantity | O16: Multiplier | Q16: Mult. Val. | S16: Sub Total
A17: 1 | C17: Machining Setup, Install and remove | F17: Setup the laser cut machine | I17: 1.3 | K17: Unit | M17: 1 | O17: - | Q17: 1 | S17: =I17*M17*Q17 -> 1.3
A18: 2 | C18: Laser Cut | F18: Cutting Main Hoop | I18: 0.01 | K18: cm | M18: 14.46 | O18: Material - Steel | Q18: 3 | S18: =I18*M18*Q18 -> 0.4338
A19: 3 | C19: Tube bends | F19: Main Hoop bend | I19: 0.75 | K19: bend | M19: 3 | O19: - | Q19: 1 | S19: =I19*M19*Q19 -> 2.25
Q20: Sub Total | S20: =SUM(S19:T19,S18:T18,S17:T17) -> 3.9838
A22: Item Order | C22: Fastener | F22: Use | I22: Unit Cost | K22: Size ( 1 ) | M22: Unit ( 1 ) | O22: Size ( 2 ) | Q22: Unit ( 2 ) | S22: Quantity | U22: Sub Total
S25: Sub Total
A27: Item Order | C27: Tooling | F27: Use | I27: Unit Cost | K27: Unit | M27: Quantity | O27: PVF | Q27: Frac Incld. | S27: Sub Total
Q30: Sub Total

Sheet FR 00227-AA
A1: University | C1: King Mongkut's University of Techonology Thonburi | L1: Car # | N1: EV-02 | T1: Part Cost | V1: =AA14+S20+U25+S30 -> 4.9867
A2: System | C2: FR | T2: Qty | V2: 1
A3: Assembly | C3: Frame Assembly | L3: Filelink1
A4: Part | C4: Sholder Hardness | L4: Filelink 2 | T4: Extended Cost | V4: =V1*V2 -> 4.9867
A5: P/N Base | C5: 00227 | L5: Filelink 3
A6: Suffix | C6: AA
A7: Details
A11: Item Order | C11: Material | F11: Use | I11: Unit Cost | K11: Size ( 1 ) | M11: Unit ( 1 ) | O11: Size ( 2 ) | Q11: Unit ( 2 ) | S11: Area Name | U11: Area | V11: Length | W11: Density | Y11: Quantity | AA11: Sub Total
A12: 1 | C12: Tubing, Steel | F12: Frame tube | I12: 2.25 | K12: 0.71 | M12: kg | O12: - | Q12: - | S12: Circle | U12: 91.27 mm^2 | V12: 520 mm | W12: - | Y12: 1 | AA12: =I12*K12*Y12 -> 1.5975
Y14: Sub Total | AA14: =SUM(AA12:AB13) -> 1.5975
A16: Item Order | C16: Process | F16: Use | I16: Unit Cost | K16: Unit | M16: Quantity | O16: Multiplier | Q16: Mult. Val. | S16: Sub Total
A17: 1 | C17: Machining Setup, Install and remove | F17: Setup the laser cut machine | I17: 1.3 | K17: Unit | M17: 1 | O17: - | Q17: 1 | S17: =I17*M17*Q17 -> 1.3
A18: 2 | C18: Laser Cut | F18: Cutting tube | I18: 0.01 | K18: cm | M18: 19.64 | O18: Material - Steel | Q18: 3 | S18: =I18*M18*Q18 -> 0.5892
A19: 1 | C19: Tube bends | F19: Sholder hardness bends | I19: 0.75 | K19: bend | M19: 2 | O19: - | Q19: 1 | S19: =I19*M19*Q19 -> 1.5
Q20: Sub Total | S20: =SUM(S17:S19) -> 3.3892
A22: Item Order | C22: Fastener | F22: Use | I22: Unit Cost | K22: Size ( 1 ) | M22: Unit ( 1 ) | O22: Size ( 2 ) | Q22: Unit ( 2 ) | S22: Quantity | U22: Sub Total
S25: Sub Total
A27: Item Order | C27: Tooling | F27: Use | I27: Unit Cost | K27: Unit | M27: Quantity | O27: PVF | Q27: Frac Incld. | S27: Sub Total
Q30: Sub Total

Sheet FR 00228-AA
A1: University | C1: King Mongkut's University of Techonology Thonburi | L1: Car # | N1: EV-02 | T1: Part Cost | V1: =AA14+S19+U24+S29 -> 2.2285
A2: System | C2: FR | T2: Qty | V2: 1
A3: Assembly | C3: Frame Assembly | L3: Filelink1
A4: Part | C4: Sholder Hardness Braces 2 | L4: Filelink 2 | T4: Extended Cost | V4: =V1*V2 -> 2.2285
A5: P/N Base | C5: 00228 | L5: Filelink 3
A6: Suffix | C6: AA
A7: Details
A11: Item Order | C11: Material | F11: Use | I11: Unit Cost | K11: Size ( 1 ) | M11: Unit ( 1 ) | O11: Size ( 2 ) | Q11: Unit ( 2 ) | S11: Area Name | U11: Area | V11: Length | W11: Density | Y11: Quantity | AA11: Sub Total
A12: 1 | C12: Tubing, Steel | F12: Frame tube | I12: 2.25 | K12: 0.07 | M12: kg | O12: - | Q12: - | S12: Circle | U12: 91.27 mm^2 | V12: 102.49 mm | W12: - | Y12: 1 | AA12: =I12*K12*Y12 -> 0.1575
Y14: Sub Total | AA14: =SUM(AA12:AB13) -> 0.1575
A16: Item Order | C16: Process | F16: Use | I16: Unit Cost | K16: Unit | M16: Quantity | O16: Multiplier | Q16: Mult. Val. | S16: Sub Total
